Workbook

Sheet Ref_Continente
A1: Pais (Partner) | B1: Continente
A2: Algeria | B2: Africa
A3: Areas, nes | B3: Sin clasificar
A4: Argentina | B4: South America
A5: Armenia | B5: Asia
A6: Aruba | B6: North America
A7: Australia | B7: Oceania
A8: Austria | B8: Europe
A9: Azerbaijan | B9: Asia
A10: Bahamas | B10: North America
A11: Bahrain | B11: Asia
A12: Belarus | B12: Europe
... A113: Viet Nam | B113: Asia

Sheet Ref_Acuerdos
A1: Pais (Partner) | B1: Tipo (FTA/PTA) | C1: Año inicio vigencia | D1: Tariff (%) | E1: Fuente / Nota
A2: Argentina | B2: PTA | C2: 2008 | D2: 5 | E2: Ecuador-Mercosur ACE 59 - preferencias parciales (tarifa referencial)
A3: Austria | B3: FTA | C3: 2017 | D3: 0 | E3: UE-Ecuador Acuerdo Multipartes, vigente desde ene-2017
A4: Belgium | B4: FTA | C4: 2017 | D4: 0 | E4: UE-Ecuador Acuerdo Multipartes, vigente desde ene-2017
A5: Bolivia (Plurinational State of) | B5: PTA | C5: 2008 | D5: 0 | E5: Comunidad Andina (CAN) - libre comercio intracomunitario
A6: Brazil | B6: PTA | C6: 2008 | D6: 5 | E6: Ecuador-Mercosur ACE 59 - preferencias parciales (tarifa referencial)
A7: Bulgaria | B7: FTA | C7: 2017 | D7: 0 | E7: UE-Ecuador Acuerdo Multipartes, vigente desde ene-2017
A8: Chile | B8: FTA | C8: 2010 | D8: 0 | E8: Ecuador-Chile ACE 65, vigente desde 2010
A9: China | B9: FTA | C9: 2024 | D9: 0 | E9: Ecuador-China TLC, vigente desde may-2024
A10: Colombia | B10: PTA | C10: 2008 | D10: 0 | E10: Comunidad Andina (CAN) - libre comercio intracomunitario
A11: Costa Rica | B11: FTA | C11: 2024 | D11: 0 | E11: Ecuador-Costa Rica TLC, vigente desde oct-2024
A12: Croatia | B12: FTA | C12: 2017 | D12: 0 | E12: UE-Ecuador Acuerdo Multipartes, vigente desde ene-2017
A13: Cuba | B13: PTA | C13: 2008 | D13: 10 | E13: ALADI - Acuerdo de Alcance Parcial (preferencia limitada, tarifa referencial)
... A45: Uruguay | B45: PTA | C45: 2008 | D45: 5 | E45: Ecuador-Mercosur ACE 59 - preferencias parciales (tarifa referencial)
A48: Fuentes: SICE-OEA (sice.oas.org/ctyindex/ecu), Ministerio de Produccion, Comercio Exterior e Inversiones de Ecuador (produccion.gob.ec), cobertura de prensa sobre los 13 acuerdos comerciales vigentes de Ecuador (jul-2026). Paises sin fila aqui = sin FTA/PTA identificado (arancel NMF). Tarifas de bloques sin arancel especifico publicado para esta partida son referenciales (Mercosur ACE59 ~5%, AAP ALADI ~10%) y deben verificarse.

Sheet Datos
A1: Año | B1: Pais (Partner) | C1: Continente | D1: Valor Exportado (US$) | E1: Peso Neto (kg) | F1: Distancia Ecuador (km) | G1: PIB pais importador (US$) | H1: FTA (1=Si) | I1: PTA (1=Si) | J1: Tariff aplicado (%) | K1: Fuente / Nota del acuerdo
A2: 2008 | B2: USA | C2: =IFERROR(VLOOKUP($B2,Ref_Continente!$A:$B,2,FALSE()),"Sin clasificar") -> North America | D2: 209615 | E2: 33543 | F2: 4550 | G2: 14769857911000 | H2: =IFERROR(IF(AND(VLOOKUP($B2,Ref_Acuerdos!$A:$E,2,FALSE())="FTA",$A2>=VLOOKUP($B2,Ref_Acuerdos!$A:$E,3,FALSE())),1,0),0) -> 0 | I2: =IFERROR(IF(AND(VLOOKUP($B2,Ref_Acuerdos!$A:$E,2,FALSE())="PTA",$A2>=VLOOKUP($B2,Ref_Acuerdos!$A:$E,3,FALSE())),1,0),0) -> 0 | J2: =IFERROR(IF($A2>=VLOOKUP($B2,Ref_Acuerdos!$A:$E,3,FALSE()),VLOOKUP($B2,Ref_Acuerdos!$A:$E,4,FALSE()),""),"") | K2: =IFERROR(IF($A2>=VLOOKUP($B2,Ref_Acuerdos!$A:$E,3,FALSE()),VLOOKUP($B2,Ref_Acuerdos!$A:$E,5,FALSE()),"Sin FTA/PTA vigente ese año - arancel NMF"),"Sin FTA/PTA identificado - arancel NMF") -> Sin FTA/PTA identificado - arancel NMF
A3: 2008 | B3: Netherlands | C3: =IFERROR(VLOOKUP($B3,Ref_Continente!$A:$B,2,FALSE()),"Sin clasificar") -> Europe | D3: 177619 | E3: 3628 | F3: 9300 | G3: 9.5790157e+11 | H3: =IFERROR(IF(AND(VLOOKUP($B3,Ref_Acuerdos!$A:$E,2,FALSE())="FTA",$A3>=VLOOKUP($B3,Ref_Acuerdos!$A:$E,3,FALSE())),1,0),0) -> 0 | I3: =IFERROR(IF(AND(VLOOKUP($B3,Ref_Acuerdos!$A:$E,2,FALSE())="PTA",$A3>=VLOOKUP($B3,Ref_Acuerdos!$A:$E,3,FALSE())),1,0),0) -> 0 | J3: =IFERROR(IF($A3>=VLOOKUP($B3,Ref_Acuerdos!$A:$E,3,FALSE()),VLOOKUP($B3,Ref_Acuerdos!$A:$E,4,FALSE()),""),"") | K3: =IFERROR(IF($A3>=VLOOKUP($B3,Ref_Acuerdos!$A:$E,3,FALSE()),VLOOKUP($B3,Ref_Acuerdos!$A:$E,5,FALSE()),"Sin FTA/PTA vigente ese año - arancel NMF"),"Sin FTA/PTA identificado - arancel NMF") -> Sin FTA/PTA vigente ese año - arancel NMF
A4: 2008 | B4: Russian Federation | C4: =IFERROR(VLOOKUP($B4,Ref_Continente!$A:$B,2,FALSE()),"Sin clasificar") -> Europe | D4: 104941 | E4: 12157 | F4: 12000 | G4: 1.6608481e+12 | H4: =IFERROR(IF(AND(VLOOKUP($B4,Ref_Acuerdos!$A:$E,2,FALSE())="FTA",$A4>=VLOOKUP($B4,Ref_Acuerdos!$A:$E,3,FALSE())),1,0),0) -> 0 | I4: =IFERROR(IF(AND(VLOOKUP($B4,Ref_Acuerdos!$A:$E,2,FALSE())="PTA",$A4>=VLOOKUP($B4,Ref_Acuerdos!$A:$E,3,FALSE())),1,0),0) -> 0 | J4: =IFERROR(IF($A4>=VLOOKUP($B4,Ref_Acuerdos!$A:$E,3,FALSE()),VLOOKUP($B4,Ref_Acuerdos!$A:$E,4,FALSE()),""),"") | K4: =IFERROR(IF($A4>=VLOOKUP($B4,Ref_Acuerdos!$A:$E,3,FALSE()),VLOOKUP($B4,Ref_Acuerdos!$A:$E,5,FALSE()),"Sin FTA/PTA vigente ese año - arancel NMF"),"Sin FTA/PTA identificado - arancel NMF") -> Sin FTA/PTA identificado - arancel NMF
A5: 2008 | B5: Panama | C5: =IFERROR(VLOOKUP($B5,Ref_Continente!$A:$B,2,FALSE()),"Sin clasificar") -> North America | D5: 19799 | E5: 3539 | F5: 1020 | G5: 2.5721328e+10 | H5: =IFERROR(IF(AND(VLOOKUP($B5,Ref_Acuerdos!$A:$E,2,FALSE())="FTA",$A5>=VLOOKUP($B5,Ref_Acuerdos!$A:$E,3,FALSE())),1,0),0) -> 0 | I5: =IFERROR(IF(AND(VLOOKUP($B5,Ref_Acuerdos!$A:$E,2,FALSE())="PTA",$A5>=VLOOKUP($B5,Ref_Acuerdos!$A:$E,3,FALSE())),1,0),0) -> 1 | J5: =IFERROR(IF($A5>=VLOOKUP($B5,Ref_Acuerdos!$A:$E,3,FALSE()),VLOOKUP($B5,Ref_Acuerdos!$A:$E,4,FALSE()),""),"") -> 10 | K5: =IFERROR(IF($A5>=VLOOKUP($B5,Ref_Acuerdos!$A:$E,3,FALSE()),VLOOKUP($B5,Ref_Acuerdos!$A:$E,5,FALSE()),"Sin FTA/PTA vigente ese año - arancel NMF"),"Sin FTA/PTA identificado - arancel NMF") -> ALADI - Acuerdo de Alcance Parcial (preferencia limitada, tarifa referencial)
A6: 2008 | B6: Colombia | C6: =IFERROR(VLOOKUP($B6,Ref_Continente!$A:$B,2,FALSE()),"Sin clasificar") -> South America | D6: 13200 | E6: 15 | F6: 720 | G6: 2.4250415e+11 | H6: =IFERROR(IF(AND(VLOOKUP($B6,Ref_Acuerdos!$A:$E,2,FALSE())="FTA",$A6>=VLOOKUP($B6,Ref_Acuerdos!$A:$E,3,FALSE())),1,0),0) -> 0 | I6: =IFERROR(IF(AND(VLOOKUP($B6,Ref_Acuerdos!$A:$E,2,FALSE())="PTA",$A6>=VLOOKUP($B6,Ref_Acuerdos!$A:$E,3,FALSE())),1,0),0) -> 1 | J6: =IFERROR(IF($A6>=VLOOKUP($B6,Ref_Acuerdos!$A:$E,3,FALSE()),VLOOKUP($B6,Ref_Acuerdos!$A:$E,4,FALSE()),""),"") -> 0 | K6: =IFERROR(IF($A6>=VLOOKUP($B6,Ref_Acuerdos!$A:$E,3,FALSE()),VLOOKUP($B6,Ref_Acuerdos!$A:$E,5,FALSE()),"Sin FTA/PTA vigente ese año - arancel NMF"),"Sin FTA/PTA identificado - arancel NMF") -> Comunidad Andina (CAN) - libre comercio intracomunitario
A7: 2008 | B7: Netherlands Antilles (...2010) | C7: =IFERROR(VLOOKUP($B7,Ref_Continente!$A:$B,2,FALSE()),"Sin clasificar") -> North America | D7: 11547 | E7: 273 | F7: 2250 | H7: =IFERROR(IF(AND(VLOOKUP($B7,Ref_Acuerdos!$A:$E,2,FALSE())="FTA",$A7>=VLOOKUP($B7,Ref_Acuerdos!$A:$E,3,FALSE())),1,0),0) -> 0 | I7: =IFERROR(IF(AND(VLOOKUP($B7,Ref_Acuerdos!$A:$E,2,FALSE())="PTA",$A7>=VLOOKUP($B7,Ref_Acuerdos!$A:$E,3,FALSE())),1,0),0) -> 0 | J7: =IFERROR(IF($A7>=VLOOKUP($B7,Ref_Acuerdos!$A:$E,3,FALSE()),VLOOKUP($B7,Ref_Acuerdos!$A:$E,4,FALSE()),""),"") | K7: =IFERROR(IF($A7>=VLOOKUP($B7,Ref_Acuerdos!$A:$E,3,FALSE()),VLOOKUP($B7,Ref_Acuerdos!$A:$E,5,FALSE()),"Sin FTA/PTA vigente ese año - arancel NMF"),"Sin FTA/PTA identificado - arancel NMF") -> Sin FTA/PTA identificado - arancel NMF
A8: 2008 | B8: Dominican Rep. | C8: =IFERROR(VLOOKUP($B8,Ref_Continente!$A:$B,2,FALSE()),"Sin clasificar") -> North America | D8: 6105 | E8: 1072 | F8: 2200 | G8: 4.8091434e+10 | H8: =IFERROR(IF(AND(VLOOKUP($B8,Ref_Acuerdos!$A:$E,2,FALSE())="FTA",$A8>=VLOOKUP($B8,Ref_Acuerdos!$A:$E,3,FALSE())),1,0),0) -> 0 | I8: =IFERROR(IF(AND(VLOOKUP($B8,Ref_Acuerdos!$A:$E,2,FALSE())="PTA",$A8>=VLOOKUP($B8,Ref_Acuerdos!$A:$E,3,FALSE())),1,0),0) -> 0 | J8: =IFERROR(IF($A8>=VLOOKUP($B8,Ref_Acuerdos!$A:$E,3,FALSE()),VLOOKUP($B8,Ref_Acuerdos!$A:$E,4,FALSE()),""),"") | K8: =IFERROR(IF($A8>=VLOOKUP($B8,Ref_Acuerdos!$A:$E,3,FALSE()),VLOOKUP($B8,Ref_Acuerdos!$A:$E,5,FALSE()),"Sin FTA/PTA vigente ese año - arancel NMF"),"Sin FTA/PTA identificado - arancel NMF") -> Sin FTA/PTA identificado - arancel NMF
A9: 2008 | B9: Canada | C9: =IFERROR(VLOOKUP($B9,Ref_Continente!$A:$B,2,FALSE()),"Sin clasificar") -> North America | D9: 3648 | E9: 715 | F9: 5900 | G9: 1.5529897e+12 | H9: =IFERROR(IF(AND(VLOOKUP($B9,Ref_Acuerdos!$A:$E,2,FALSE())="FTA",$A9>=VLOOKUP($B9,Ref_Acuerdos!$A:$E,3,FALSE())),1,0),0) -> 0 | I9: =IFERROR(IF(AND(VLOOKUP($B9,Ref_Acuerdos!$A:$E,2,FALSE())="PTA",$A9>=VLOOKUP($B9,Ref_Acuerdos!$A:$E,3,FALSE())),1,0),0) -> 0 | J9: =IFERROR(IF($A9>=VLOOKUP($B9,Ref_Acuerdos!$A:$E,3,FALSE()),VLOOKUP($B9,Ref_Acuerdos!$A:$E,4,FALSE()),""),"") | K9: =IFERROR(IF($A9>=VLOOKUP($B9,Ref_Acuerdos!$A:$E,3,FALSE()),VLOOKUP($B9,Ref_Acuerdos!$A:$E,5,FALSE()),"Sin FTA/PTA vigente ese año - arancel NMF"),"Sin FTA/PTA identificado - arancel NMF") -> Sin FTA/PTA identificado - arancel NMF
A10: 2008 | B10: Spain | C10: =IFERROR(VLOOKUP($B10,Ref_Continente!$A:$B,2,FALSE()),"Sin clasificar") -> Europe | D10: 2509 | E10: 442 | F10: 8700 | G10: 1.6361154e+12 | H10: =IFERROR(IF(AND(VLOOKUP($B10,Ref_Acuerdos!$A:$E,2,FALSE())="FTA",$A10>=VLOOKUP($B10,Ref_Acuerdos!$A:$E,3,FALSE())),1,0),0) -> 0 | I10: =IFERROR(IF(AND(VLOOKUP($B10,Ref_Acuerdos!$A:$E,2,FALSE())="PTA",$A10>=VLOOKUP($B10,Ref_Acuerdos!$A:$E,3,FALSE())),1,0),0) -> 0 | J10: =IFERROR(IF($A10>=VLOOKUP($B10,Ref_Acuerdos!$A:$E,3,FALSE()),VLOOKUP($B10,Ref_Acuerdos!$A:$E,4,FALSE()),""),"") | K10: =IFERROR(IF($A10>=VLOOKUP($B10,Ref_Acuerdos!$A:$E,3,FALSE()),VLOOKUP($B10,Ref_Acuerdos!$A:$E,5,FALSE()),"Sin FTA/PTA vigente ese año - arancel NMF"),"Sin FTA/PTA identificado - arancel NMF") -> Sin FTA/PTA vigente ese año - arancel NMF
A11: 2008 | B11: Free Zones | C11: =IFERROR(VLOOKUP($B11,Ref_Continente!$A:$B,2,FALSE()),"Sin clasificar") -> Sin clasificar | D11: 2029 | E11: 539 | F11: 0 | H11: =IFERROR(IF(AND(VLOOKUP($B11,Ref_Acuerdos!$A:$E,2,FALSE())="FTA",$A11>=VLOOKUP($B11,Ref_Acuerdos!$A:$E,3,FALSE())),1,0),0) -> 0 | I11: =IFERROR(IF(AND(VLOOKUP($B11,Ref_Acuerdos!$A:$E,2,FALSE())="PTA",$A11>=VLOOKUP($B11,Ref_Acuerdos!$A:$E,3,FALSE())),1,0),0) -> 0 | J11: =IFERROR(IF($A11>=VLOOKUP($B11,Ref_Acuerdos!$A:$E,3,FALSE()),VLOOKUP($B11,Ref_Acuerdos!$A:$E,4,FALSE()),""),"") | K11: =IFERROR(IF($A11>=VLOOKUP($B11,Ref_Acuerdos!$A:$E,3,FALSE()),VLOOKUP($B11,Ref_Acuerdos!$A:$E,5,FALSE()),"Sin FTA/PTA vigente ese año - arancel NMF"),"Sin FTA/PTA identificado - arancel NMF") -> Sin FTA/PTA identificado - arancel NMF
A12: 2008 | B12: Chile | C12: =IFERROR(VLOOKUP($B12,Ref_Continente!$A:$B,2,FALSE()),"Sin clasificar") -> South America | D12: 1210 | E12: 440 | F12: 2600 | G12: 1.7989459e+11 | H12: =IFERROR(IF(AND(VLOOKUP($B12,Ref_Acuerdos!$A:$E,2,FALSE())="FTA",$A12>=VLOOKUP($B12,Ref_Acuerdos!$A:$E,3,FALSE())),1,0),0) -> 0 | I12: =IFERROR(IF(AND(VLOOKUP($B12,Ref_Acuerdos!$A:$E,2,FALSE())="PTA",$A12>=VLOOKUP($B12,Ref_Acuerdos!$A:$E,3,FALSE())),1,0),0) -> 0 | J12: =IFERROR(IF($A12>=VLOOKUP($B12,Ref_Acuerdos!$A:$E,3,FALSE()),VLOOKUP($B12,Ref_Acuerdos!$A:$E,4,FALSE()),""),"") | K12: =IFERROR(IF($A12>=VLOOKUP($B12,Ref_Acuerdos!$A:$E,3,FALSE()),VLOOKUP($B12,Ref_Acuerdos!$A:$E,5,FALSE()),"Sin FTA/PTA vigente ese año - arancel NMF"),"Sin FTA/PTA identificado - arancel NMF") -> Sin FTA/PTA vigente ese año - arancel NMF
A13: 2008 | B13: China, Hong Kong SAR | C13: =IFERROR(VLOOKUP($B13,Ref_Continente!$A:$B,2,FALSE()),"Sin clasificar") -> Asia | D13: 1175 | E13: 147 | F13: 17700 | G13: 2.1927875e+11 | H13: =IFERROR(IF(AND(VLOOKUP($B13,Ref_Acuerdos!$A:$E,2,FALSE())="FTA",$A13>=VLOOKUP($B13,Ref_Acuerdos!$A:$E,3,FALSE())),1,0),0) -> 0 | I13: =IFERROR(IF(AND(VLOOKUP($B13,Ref_Acuerdos!$A:$E,2,FALSE())="PTA",$A13>=VLOOKUP($B13,Ref_Acuerdos!$A:$E,3,FALSE())),1,0),0) -> 0 | J13: =IFERROR(IF($A13>=VLOOKUP($B13,Ref_Acuerdos!$A:$E,3,FALSE()),VLOOKUP($B13,Ref_Acuerdos!$A:$E,4,FALSE()),""),"") | K13: =IFERROR(IF($A13>=VLOOKUP($B13,Ref_Acuerdos!$A:$E,3,FALSE()),VLOOKUP($B13,Ref_Acuerdos!$A:$E,5,FALSE()),"Sin FTA/PTA vigente ese año - arancel NMF"),"Sin FTA/PTA identificado - arancel NMF") -> Sin FTA/PTA identificado - arancel NMF
A14: 2008 | B14: Germany | C14: =IFERROR(VLOOKUP($B14,Ref_Continente!$A:$B,2,FALSE()),"Sin clasificar") -> Europe | D14: 661 | E14: 212 | F14: 9650 | G14: 3808197720125 | H14: =IFERROR(IF(AND(VLOOKUP($B14,Ref_Acuerdos!$A:$E,2,FALSE())="FTA",$A14>=VLOOKUP($B14,Ref_Acuerdos!$A:$E,3,FALSE())),1,0),0) -> 0 | I14: =IFERROR(IF(AND(VLOOKUP($B14,Ref_Acuerdos!$A:$E,2,FALSE())="PTA",$A14>=VLOOKUP($B14,Ref_Acuerdos!$A:$E,3,FALSE())),1,0),0) -> 0 | J14: =IFERROR(IF($A14>=VLOOKUP($B14,Ref_Acuerdos!$A:$E,3,FALSE()),VLOOKUP($B14,Ref_Acuerdos!$A:$E,4,FALSE()),""),"") | K14: =IFERROR(IF($A14>=VLOOKUP($B14,Ref_Acuerdos!$A:$E,3,FALSE()),VLOOKUP($B14,Ref_Acuerdos!$A:$E,5,FALSE()),"Sin FTA/PTA vigente ese año - arancel NMF"),"Sin FTA/PTA identificado - arancel NMF") -> Sin FTA/PTA vigente ese año - arancel NMF
A15: 2008 | B15: France | C15: =IFERROR(VLOOKUP($B15,Ref_Continente!$A:$B,2,FALSE()),"Sin clasificar") -> Europe | D15: 436 | E15: 127 | F15: 9150 | G15: 2.9268029e+12 | H15: =IFERROR(IF(AND(VLOOKUP($B15,Ref_Acuerdos!$A:$E,2,FALSE())="FTA",$A15>=VLOOKUP($B15,Ref_Acuerdos!$A:$E,3,FALSE())),1,0),0) -> 0 | I15: =IFERROR(IF(AND(VLOOKUP($B15,Ref_Acuerdos!$A:$E,2,FALSE())="PTA",$A15>=VLOOKUP($B15,Ref_Acuerdos!$A:$E,3,FALSE())),1,0),0) -> 0 | J15: =IFERROR(IF($A15>=VLOOKUP($B15,Ref_Acuerdos!$A:$E,3,FALSE()),VLOOKUP($B15,Ref_Acuerdos!$A:$E,4,FALSE()),""),"") | K15: =IFERROR(IF($A15>=VLOOKUP($B15,Ref_Acuerdos!$A:$E,3,FALSE()),VLOOKUP($B15,Ref_Acuerdos!$A:$E,5,FALSE()),"Sin FTA/PTA vigente ese año - arancel NMF"),"Sin FTA/PTA identificado - arancel NMF") -> Sin FTA/PTA vigente ese año - arancel NMF
A16: 2008 | B16: Italy | C16: =IFERROR(VLOOKUP($B16,Ref_Continente!$A:$B,2,FALSE()),"Sin clasificar") -> Europe | D16: 358 | E16: 120 | F16: 10100 | G16: 2.4175084e+12 | H16: =IFERROR(IF(AND(VLOOKUP($B16,Ref_Acuerdos!$A:$E,2,FALSE())="FTA",$A16>=VLOOKUP($B16,Ref_Acuerdos!$A:$E,3,FALSE())),1,0),0) -> 0 | I16: =IFERROR(IF(AND(VLOOKUP($B16,Ref_Acuerdos!$A:$E,2,FALSE())="PTA",$A16>=VLOOKUP($B16,Ref_Acuerdos!$A:$E,3,FALSE())),1,0),0) -> 0 | J16: =IFERROR(IF($A16>=VLOOKUP($B16,Ref_Acuerdos!$A:$E,3,FALSE()),VLOOKUP($B16,Ref_Acuerdos!$A:$E,4,FALSE()),""),"") | K16: =IFERROR(IF($A16>=VLOOKUP($B16,Ref_Acuerdos!$A:$E,3,FALSE()),VLOOKUP($B16,Ref_Acuerdos!$A:$E,5,FALSE()),"Sin FTA/PTA vigente ese año - arancel NMF"),"Sin FTA/PTA identificado - arancel NMF") -> Sin FTA/PTA vigente ese año - arancel NMF
A17: 2008 | B17: Singapore | C17: =IFERROR(VLOOKUP($B17,Ref_Continente!$A:$B,2,FALSE()),"Sin clasificar") -> Asia | D17: 357 | E17: 55 | F17: 18800 | G17: 1.9361732e+11 | H17: =IFERROR(IF(AND(VLOOKUP($B17,Ref_Acuerdos!$A:$E,2,FALSE())="FTA",$A17>=VLOOKUP($B17,Ref_Acuerdos!$A:$E,3,FALSE())),1,0),0) -> 0 | I17: =IFERROR(IF(AND(VLOOKUP($B17,Ref_Acuerdos!$A:$E,2,FALSE())="PTA",$A17>=VLOOKUP($B17,Ref_Acuerdos!$A:$E,3,FALSE())),1,0),0) -> 0 | J17: =IFERROR(IF($A17>=VLOOKUP($B17,Ref_Acuerdos!$A:$E,3,FALSE()),VLOOKUP($B17,Ref_Acuerdos!$A:$E,4,FALSE()),""),"") | K17: =IFERROR(IF($A17>=VLOOKUP($B17,Ref_Acuerdos!$A:$E,3,FALSE()),VLOOKUP($B17,Ref_Acuerdos!$A:$E,5,FALSE()),"Sin FTA/PTA vigente ese año - arancel NMF"),"Sin FTA/PTA identificado - arancel NMF") -> Sin FTA/PTA identificado - arancel NMF
A18: 2008 | B18: Belgium | C18: =IFERROR(VLOOKUP($B18,Ref_Continente!$A:$B,2,FALSE()),"Sin clasificar") -> Europe | D18: 211 | E18: 36 | F18: 9350 | G18: 5.1732809e+11 | H18: =IFERROR(IF(AND(VLOOKUP($B18,Ref_Acuerdos!$A:$E,2,FALSE())="FTA",$A18>=VLOOKUP($B18,Ref_Acuerdos!$A:$E,3,FALSE())),1,0),0) -> 0 | I18: =IFERROR(IF(AND(VLOOKUP($B18,Ref_Acuerdos!$A:$E,2,FALSE())="PTA",$A18>=VLOOKUP($B18,Ref_Acuerdos!$A:$E,3,FALSE())),1,0),0) -> 0 | J18: =IFERROR(IF($A18>=VLOOKUP($B18,Ref_Acuerdos!$A:$E,3,FALSE()),VLOOKUP($B18,Ref_Acuerdos!$A:$E,4,FALSE()),""),"") | K18: =IFERROR(IF($A18>=VLOOKUP($B18,Ref_Acuerdos!$A:$E,3,FALSE()),VLOOKUP($B18,Ref_Acuerdos!$A:$E,5,FALSE()),"Sin FTA/PTA vigente ese año - arancel NMF"),"Sin FTA/PTA identificado - arancel NMF") -> Sin FTA/PTA vigente ese año - arancel NMF
A19: 2008 | B19: Guam | C19: =IFERROR(VLOOKUP($B19,Ref_Continente!$A:$B,2,FALSE()),"Sin clasificar") -> Oceania | D19: 156 | E19: 22 | F19: 14200 | G19: 4658000000 | H19: =IFERROR(IF(AND(VLOOKUP($B19,Ref_Acuerdos!$A:$E,2,FALSE())="FTA",$A19>=VLOOKUP($B19,Ref_Acuerdos!$A:$E,3,FALSE())),1,0),0) -> 0 | I19: =IFERROR(IF(AND(VLOOKUP($B19,Ref_Acuerdos!$A:$E,2,FALSE())="PTA",$A19>=VLOOKUP($B19,Ref_Acuerdos!$A:$E,3,FALSE())),1,0),0) -> 0 | J19: =IFERROR(IF($A19>=VLOOKUP($B19,Ref_Acuerdos!$A:$E,3,FALSE()),VLOOKUP($B19,Ref_Acuerdos!$A:$E,4,FALSE()),""),"") | K19: =IFERROR(IF($A19>=VLOOKUP($B19,Ref_Acuerdos!$A:$E,3,FALSE()),VLOOKUP($B19,Ref_Acuerdos!$A:$E,5,FALSE()),"Sin FTA/PTA vigente ese año - arancel NMF"),"Sin FTA/PTA identificado - arancel NMF") -> Sin FTA/PTA identificado - arancel NMF
A20: 2008 | B20: United Kingdom | C20: =IFERROR(VLOOKUP($B20,Ref_Continente!$A:$B,2,FALSE()),"Sin clasificar") -> Europe | D20: 98 | E20: 30 | F20: 9200 | G20: 2.9452518e+12 | H20: =IFERROR(IF(AND(VLOOKUP($B20,Ref_Acuerdos!$A:$E,2,FALSE())="FTA",$A20>=VLOOKUP($B20,Ref_Acuerdos!$A:$E,3,FALSE())),1,0),0) -> 0 | I20: =IFERROR(IF(AND(VLOOKUP($B20,Ref_Acuerdos!$A:$E,2,FALSE())="PTA",$A20>=VLOOKUP($B20,Ref_Acuerdos!$A:$E,3,FALSE())),1,0),0) -> 0 | J20: =IFERROR(IF($A20>=VLOOKUP($B20,Ref_Acuerdos!$A:$E,3,FALSE()),VLOOKUP($B20,Ref_Acuerdos!$A:$E,4,FALSE()),""),"") | K20: =IFERROR(IF($A20>=VLOOKUP($B20,Ref_Acuerdos!$A:$E,3,FALSE()),VLOOKUP($B20,Ref_Acuerdos!$A:$E,5,FALSE()),"Sin FTA/PTA vigente ese año - arancel NMF"),"Sin FTA/PTA identificado - arancel NMF") -> Sin FTA/PTA vigente ese año - arancel NMF
A21: 2008 | B21: Argentina | C21: =IFERROR(VLOOKUP($B21,Ref_Continente!$A:$B,2,FALSE()),"Sin clasificar") -> South America | D21: 48 | E21: 9 | F21: 4320 | G21: 3.6155804e+11 | H21: =IFERROR(IF(AND(VLOOKUP($B21,Ref_Acuerdos!$A:$E,2,FALSE())="FTA",$A21>=VLOOKUP($B21,Ref_Acuerdos!$A:$E,3,FALSE())),1,0),0) -> 0 | I21: =IFERROR(IF(AND(VLOOKUP($B21,Ref_Acuerdos!$A:$E,2,FALSE())="PTA",$A21>=VLOOKUP($B21,Ref_Acuerdos!$A:$E,3,FALSE())),1,0),0) -> 1 | J21: =IFERROR(IF($A21>=VLOOKUP($B21,Ref_Acuerdos!$A:$E,3,FALSE()),VLOOKUP($B21,Ref_Acuerdos!$A:$E,4,FALSE()),""),"") -> 5 | K21: =IFERROR(IF($A21>=VLOOKUP($B21,Ref_Acuerdos!$A:$E,3,FALSE()),VLOOKUP($B21,Ref_Acuerdos!$A:$E,5,FALSE()),"Sin FTA/PTA vigente ese año - arancel NMF"),"Sin FTA/PTA identificado - arancel NMF") -> Ecuador-Mercosur ACE 59 - preferencias parciales (tarifa referencial)
A22: 2009 | B22: Russian Federation | C22: =IFERROR(VLOOKUP($B22,Ref_Continente!$A:$B,2,FALSE()),"Sin clasificar") -> Europe | D22: 3058726 | E22: 777809 | F22: 12000 | G22: 1.2226459e+12 | H22: =IFERROR(IF(AND(VLOOKUP($B22,Ref_Acuerdos!$A:$E,2,FALSE())="FTA",$A22>=VLOOKUP($B22,Ref_Acuerdos!$A:$E,3,FALSE())),1,0),0) -> 0 | I22: =IFERROR(IF(AND(VLOOKUP($B22,Ref_Acuerdos!$A:$E,2,FALSE())="PTA",$A22>=VLOOKUP($B22,Ref_Acuerdos!$A:$E,3,FALSE())),1,0),0) -> 0 | J22: =IFERROR(IF($A22>=VLOOKUP($B22,Ref_Acuerdos!$A:$E,3,FALSE()),VLOOKUP($B22,Ref_Acuerdos!$A:$E,4,FALSE()),""),"") | K22: =IFERROR(IF($A22>=VLOOKUP($B22,Ref_Acuerdos!$A:$E,3,FALSE()),VLOOKUP($B22,Ref_Acuerdos!$A:$E,5,FALSE()),"Sin FTA/PTA vigente ese año - arancel NMF"),"Sin FTA/PTA identificado - arancel NMF") -> Sin FTA/PTA identificado - arancel NMF
A23: 2009 | B23: USA | C23: =IFERROR(VLOOKUP($B23,Ref_Continente!$A:$B,2,FALSE()),"Sin clasificar") -> North America | D23: 1985662 | E23: 326492 | F23: 4550 | G23: 14478064934000 | H23: =IFERROR(IF(AND(VLOOKUP($B23,Ref_Acuerdos!$A:$E,2,FALSE())="FTA",$A23>=VLOOKUP($B23,Ref_Acuerdos!$A:$E,3,FALSE())),1,0),0) -> 0 | I23: =IFERROR(IF(AND(VLOOKUP($B23,Ref_Acuerdos!$A:$E,2,FALSE())="PTA",$A23>=VLOOKUP($B23,Ref_Acuerdos!$A:$E,3,FALSE())),1,0),0) -> 0 | J23: =IFERROR(IF($A23>=VLOOKUP($B23,Ref_Acuerdos!$A:$E,3,FALSE()),VLOOKUP($B23,Ref_Acuerdos!$A:$E,4,FALSE()),""),"") | K23: =IFERROR(IF($A23>=VLOOKUP($B23,Ref_Acuerdos!$A:$E,3,FALSE()),VLOOKUP($B23,Ref_Acuerdos!$A:$E,5,FALSE()),"Sin FTA/PTA vigente ese año - arancel NMF"),"Sin FTA/PTA identificado - arancel NMF") -> Sin FTA/PTA identificado - arancel NMF
... A29: 2009 | B29: Colombia | C29: =IFERROR(VLOOKUP($B29,Ref_Continente!$A:$B,2,FALSE()),"Sin clasificar") -> South America | D29: 166414 | E29: 47787 | F29: 720 | G29: 2.3246866e+11 | H29: =IFERROR(IF(AND(VLOOKUP($B29,Ref_Acuerdos!$A:$E,2,FALSE())="FTA",$A29>=VLOOKUP($B29,Ref_Acuerdos!$A:$E,3,FALSE())),1,0),0) -> 0 | I29: =IFERROR(IF(AND(VLOOKUP($B29,Ref_Acuerdos!$A:$E,2,FALSE())="PTA",$A29>=VLOOKUP($B29,Ref_Acuerdos!$A:$E,3,FALSE())),1,0),0) -> 1 | J29: =IFERROR(IF($A29>=VLOOKUP($B29,Ref_Acuerdos!$A:$E,3,FALSE()),VLOOKUP($B29,Ref_Acuerdos!$A:$E,4,FALSE()),""),"") -> 0 | K29: =IFERROR(IF($A29>=VLOOKUP($B29,Ref_Acuerdos!$A:$E,3,FALSE()),VLOOKUP($B29,Ref_Acuerdos!$A:$E,5,FALSE()),"Sin FTA/PTA vigente ese año - arancel NMF"),"Sin FTA/PTA identificado - arancel NMF") -> Comunidad Andina (CAN) - libre comercio intracomunitario
A30: 2009 | B30: Netherlands Antilles (...2010) | C30: =IFERROR(VLOOKUP($B30,Ref_Continente!$A:$B,2,FALSE()),"Sin clasificar") -> North America | D30: 104817 | E30: 27726 | F30: 2250 | H30: =IFERROR(IF(AND(VLOOKUP($B30,Ref_Acuerdos!$A:$E,2,FALSE())="FTA",$A30>=VLOOKUP($B30,Ref_Acuerdos!$A:$E,3,FALSE())),1,0),0) -> 0 | I30: =IFERROR(IF(AND(VLOOKUP($B30,Ref_Acuerdos!$A:$E,2,FALSE())="PTA",$A30>=VLOOKUP($B30,Ref_Acuerdos!$A:$E,3,FALSE())),1,0),0) -> 0 | J30: =IFERROR(IF($A30>=VLOOKUP($B30,Ref_Acuerdos!$A:$E,3,FALSE()),VLOOKUP($B30,Ref_Acuerdos!$A:$E,4,FALSE()),""),"") | K30: =IFERROR(IF($A30>=VLOOKUP($B30,Ref_Acuerdos!$A:$E,3,FALSE()),VLOOKUP($B30,Ref_Acuerdos!$A:$E,5,FALSE()),"Sin FTA/PTA vigente ese año - arancel NMF"),"Sin FTA/PTA identificado - arancel NMF") -> Sin FTA/PTA identificado - arancel NMF
A31: 2009 | B31: Australia | C31: =IFERROR(VLOOKUP($B31,Ref_Continente!$A:$B,2,FALSE()),"Sin clasificar") -> Oceania | D31: 70321 | E31: 18122 | F31: 14000 | G31: 9.3176169e+11 | H31: =IFERROR(IF(AND(VLOOKUP($B31,Ref_Acuerdos!$A:$E,2,FALSE())="FTA",$A31>=VLOOKUP($B31,Ref_Acuerdos!$A:$E,3,FALSE())),1,0),0) -> 0 | I31: =IFERROR(IF(AND(VLOOKUP($B31,Ref_Acuerdos!$A:$E,2,FALSE())="PTA",$A31>=VLOOKUP($B31,Ref_Acuerdos!$A:$E,3,FALSE())),1,0),0) -> 0 | J31: =IFERROR(IF($A31>=VLOOKUP($B31,Ref_Acuerdos!$A:$E,3,FALSE()),VLOOKUP($B31,Ref_Acuerdos!$A:$E,4,FALSE()),""),"") | K31: =IFERROR(IF($A31>=VLOOKUP($B31,Ref_Acuerdos!$A:$E,3,FALSE()),VLOOKUP($B31,Ref_Acuerdos!$A:$E,5,FALSE()),"Sin FTA/PTA vigente ese año - arancel NMF"),"Sin FTA/PTA identificado - arancel NMF") -> Sin FTA/PTA identificado - arancel NMF
A32: 2009 | B32: Panama | C32: =IFERROR(VLOOKUP($B32,Ref_Continente!$A:$B,2,FALSE()),"Sin clasificar") -> North America | D32: 58156 | E32: 14669 | F32: 1020 | G32: 2.7791216e+10 | H32: =IFERROR(IF(AND(VLOOKUP($B32,Ref_Acuerdos!$A:$E,2,FALSE())="FTA",$A32>=VLOOKUP($B32,Ref_Acuerdos!$A:$E,3,FALSE())),1,0),0) -> 0 | I32: =IFERROR(IF(AND(VLOOKUP($B32,Ref_Acuerdos!$A:$E,2,FALSE())="PTA",$A32>=VLOOKUP($B32,Ref_Acuerdos!$A:$E,3,FALSE())),1,0),0) -> 1 | J32: =IFERROR(IF($A32>=VLOOKUP($B32,Ref_Acuerdos!$A:$E,3,FALSE()),VLOOKUP($B32,Ref_Acuerdos!$A:$E,4,FALSE()),""),"") -> 10 | K32: =IFERROR(IF($A32>=VLOOKUP($B32,Ref_Acuerdos!$A:$E,3,FALSE()),VLOOKUP($B32,Ref_Acuerdos!$A:$E,5,FALSE()),"Sin FTA/PTA vigente ese año - arancel NMF"),"Sin FTA/PTA identificado - arancel NMF") -> ALADI - Acuerdo de Alcance Parcial (preferencia limitada, tarifa referencial)
A33: 2009 | B33: Canada | C33: =IFERROR(VLOOKUP($B33,Ref_Continente!$A:$B,2,FALSE()),"Sin clasificar") -> North America | D33: 47391 | E33: 11929 | F33: 5900 | G33: 1.3746251e+12 | H33: =IFERROR(IF(AND(VLOOKUP($B33,Ref_Acuerdos!$A:$E,2,FALSE())="FTA",$A33>=VLOOKUP($B33,Ref_Acuerdos!$A:$E,3,FALSE())),1,0),0) -> 0 | I33: =IFERROR(IF(AND(VLOOKUP($B33,Ref_Acuerdos!$A:$E,2,FALSE())="PTA",$A33>=VLOOKUP($B33,Ref_Acuerdos!$A:$E,3,FALSE())),1,0),0) -> 0 | J33: =IFERROR(IF($A33>=VLOOKUP($B33,Ref_Acuerdos!$A:$E,3,FALSE()),VLOOKUP($B33,Ref_Acuerdos!$A:$E,4,FALSE()),""),"") | K33: =IFERROR(IF($A33>=VLOOKUP($B33,Ref_Acuerdos!$A:$E,3,FALSE()),VLOOKUP($B33,Ref_Acuerdos!$A:$E,5,FALSE()),"Sin FTA/PTA vigente ese año - arancel NMF"),"Sin FTA/PTA identificado - arancel NMF") -> Sin FTA/PTA identificado - arancel NMF
A34: 2009 | B34: Germany | C34: =IFERROR(VLOOKUP($B34,Ref_Continente!$A:$B,2,FALSE()),"Sin clasificar") -> Europe | D34: 39339 | E34: 9814 | F34: 9650 | G34: 3.4785455e+12 | H34: =IFERROR(IF(AND(VLOOKUP($B34,Ref_Acuerdos!$A:$E,2,FALSE())="FTA",$A34>=VLOOKUP($B34,Ref_Acuerdos!$A:$E,3,FALSE())),1,0),0) -> 0 | I34: =IFERROR(IF(AND(VLOOKUP($B34,Ref_Acuerdos!$A:$E,2,FALSE())="PTA",$A34>=VLOOKUP($B34,Ref_Acuerdos!$A:$E,3,FALSE())),1,0),0) -> 0 | J34: =IFERROR(IF($A34>=VLOOKUP($B34,Ref_Acuerdos!$A:$E,3,FALSE()),VLOOKUP($B34,Ref_Acuerdos!$A:$E,4,FALSE()),""),"") | K34: =IFERROR(IF($A34>=VLOOKUP($B34,Ref_Acuerdos!$A:$E,3,FALSE()),VLOOKUP($B34,Ref_Acuerdos!$A:$E,5,FALSE()),"Sin FTA/PTA vigente ese año - arancel NMF"),"Sin FTA/PTA identificado - arancel NMF") -> Sin FTA/PTA vigente ese año - arancel NMF
A35: 2009 | B35: Chile | C35: =IFERROR(VLOOKUP($B35,Ref_Continente!$A:$B,2,FALSE()),"Sin clasificar") -> South America | D35: 38005 | E35: 11396 | F35: 2600 | G35: 1.717779e+11 | H35: =IFERROR(IF(AND(VLOOKUP($B35,Ref_Acuerdos!$A:$E,2,FALSE())="FTA",$A35>=VLOOKUP($B35,Ref_Acuerdos!$A:$E,3,FALSE())),1,0),0) -> 0 | I35: =IFERROR(IF(AND(VLOOKUP($B35,Ref_Acuerdos!$A:$E,2,FALSE())="PTA",$A35>=VLOOKUP($B35,Ref_Acuerdos!$A:$E,3,FALSE())),1,0),0) -> 0 | J35: =IFERROR(IF($A35>=VLOOKUP($B35,Ref_Acuerdos!$A:$E,3,FALSE()),VLOOKUP($B35,Ref_Acuerdos!$A:$E,4,FALSE()),""),"") | K35: =IFERROR(IF($A35>=VLOOKUP($B35,Ref_Acuerdos!$A:$E,3,FALSE()),VLOOKUP($B35,Ref_Acuerdos!$A:$E,5,FALSE()),"Sin FTA/PTA vigente ese año - arancel NMF"),"Sin FTA/PTA identificado - arancel NMF") -> Sin FTA/PTA vigente ese año - arancel NMF
A36: 2009 | B36: Cuba | C36: =IFERROR(VLOOKUP($B36,Ref_Continente!$A:$B,2,FALSE()),"Sin clasificar") -> North America | D36: 23008 | E36: 4374 | F36: 2450 | G36: 5.7481481e+10 | H36: =IFERROR(IF(AND(VLOOKUP($B36,Ref_Acuerdos!$A:$E,2,FALSE())="FTA",$A36>=VLOOKUP($B36,Ref_Acuerdos!$A:$E,3,FALSE())),1,0),0) -> 0 | I36: =IFERROR(IF(AND(VLOOKUP($B36,Ref_Acuerdos!$A:$E,2,FALSE())="PTA",$A36>=VLOOKUP($B36,Ref_Acuerdos!$A:$E,3,FALSE())),1,0),0) -> 1 | J36: =IFERROR(IF($A36>=VLOOKUP($B36,Ref_Acuerdos!$A:$E,3,FALSE()),VLOOKUP($B36,Ref_Acuerdos!$A:$E,4,FALSE()),""),"") -> 10 | K36: =IFERROR(IF($A36>=VLOOKUP($B36,Ref_Acuerdos!$A:$E,3,FALSE()),VLOOKUP($B36,Ref_Acuerdos!$A:$E,5,FALSE()),"Sin FTA/PTA vigente ese año - arancel NMF"),"Sin FTA/PTA identificado - arancel NMF") -> ALADI - Acuerdo de Alcance Parcial (preferencia limitada, tarifa referencial)
A37: 2009 | B37: Portugal | C37: =IFERROR(VLOOKUP($B37,Ref_Continente!$A:$B,2,FALSE()),"Sin clasificar") -> Europe | D37: 20952 | E37: 4718 | F37: 8700 | G37: 2.4466776e+11 | H37: =IFERROR(IF(AND(VLOOKUP($B37,Ref_Acuerdos!$A:$E,2,FALSE())="FTA",$A37>=VLOOKUP($B37,Ref_Acuerdos!$A:$E,3,FALSE())),1,0),0) -> 0 | I37: =IFERROR(IF(AND(VLOOKUP($B37,Ref_Acuerdos!$A:$E,2,FALSE())="PTA",$A37>=VLOOKUP($B37,Ref_Acuerdos!$A:$E,3,FALSE())),1,0),0) -> 0 | J37: =IFERROR(IF($A37>=VLOOKUP($B37,Ref_Acuerdos!$A:$E,3,FALSE()),VLOOKUP($B37,Ref_Acuerdos!$A:$E,4,FALSE()),""),"") | K37: =IFERROR(IF($A37>=VLOOKUP($B37,Ref_Acuerdos!$A:$E,3,FALSE()),VLOOKUP($B37,Ref_Acuerdos!$A:$E,5,FALSE()),"Sin FTA/PTA vigente ese año - arancel NMF"),"Sin FTA/PTA identificado - arancel NMF") -> Sin FTA/PTA vigente ese año - arancel NMF
A38: 2009 | B38: Iran | C38: =IFERROR(VLOOKUP($B38,Ref_Continente!$A:$B,2,FALSE()),"Sin clasificar") -> Asia | D38: 20282 | E38: 1998 | H38: =IFERROR(IF(AND(VLOOKUP($B38,Ref_Acuerdos!$A:$E,2,FALSE())="FTA",$A38>=VLOOKUP($B38,Ref_Acuerdos!$A:$E,3,FALSE())),1,0),0) -> 0 | I38: =IFERROR(IF(AND(VLOOKUP($B38,Ref_Acuerdos!$A:$E,2,FALSE())="PTA",$A38>=VLOOKUP($B38,Ref_Acuerdos!$A:$E,3,FALSE())),1,0),0) -> 0 | J38: =IFERROR(IF($A38>=VLOOKUP($B38,Ref_Acuerdos!$A:$E,3,FALSE()),VLOOKUP($B38,Ref_Acuerdos!$A:$E,4,FALSE()),""),"") | K38: =IFERROR(IF($A38>=VLOOKUP($B38,Ref_Acuerdos!$A:$E,3,FALSE()),VLOOKUP($B38,Ref_Acuerdos!$A:$E,5,FALSE()),"Sin FTA/PTA vigente ese año - arancel NMF"),"Sin FTA/PTA identificado - arancel NMF") -> Sin FTA/PTA identificado - arancel NMF
A39: 2009 | B39: Philippines | C39: =IFERROR(VLOOKUP($B39,Ref_Continente!$A:$B,2,FALSE()),"Sin clasificar") -> Asia | D39: 18020 | E39: 1055 | F39: 17800 | G39: 1.7597476e+11 | H39: =IFERROR(IF(AND(VLOOKUP($B39,Ref_Acuerdos!$A:$E,2,FALSE())="FTA",$A39>=VLOOKUP($B39,Ref_Acuerdos!$A:$E,3,FALSE())),1,0),0) -> 0 | I39: =IFERROR(IF(AND(VLOOKUP($B39,Ref_Acuerdos!$A:$E,2,FALSE())="PTA",$A39>=VLOOKUP($B39,Ref_Acuerdos!$A:$E,3,FALSE())),1,0),0) -> 0 | J39: =IFERROR(IF($A39>=VLOOKUP($B39,Ref_Acuerdos!$A:$E,3,FALSE()),VLOOKUP($B39,Ref_Acuerdos!$A:$E,4,FALSE()),""),"") | K39: =IFERROR(IF($A39>=VLOOKUP($B39,Ref_Acuerdos!$A:$E,3,FALSE()),VLOOKUP($B39,Ref_Acuerdos!$A:$E,5,FALSE()),"Sin FTA/PTA vigente ese año - arancel NMF"),"Sin FTA/PTA identificado - arancel NMF") -> Sin FTA/PTA identificado - arancel NMF
A40: 2009 | B40: France | C40: =IFERROR(VLOOKUP($B40,Ref_Continente!$A:$B,2,FALSE()),"Sin clasificar") -> Europe | D40: 17594 | E40: 3191 | F40: 9150 | G40: 2.7000759e+12 | H40: =IFERROR(IF(AND(VLOOKUP($B40,Ref_Acuerdos!$A:$E,2,FALSE())="FTA",$A40>=VLOOKUP($B40,Ref_Acuerdos!$A:$E,3,FALSE())),1,0),0) -> 0 | I40: =IFERROR(IF(AND(VLOOKUP($B40,Ref_Acuerdos!$A:$E,2,FALSE())="PTA",$A40>=VLOOKUP($B40,Ref_Acuerdos!$A:$E,3,FALSE())),1,0),0) -> 0 | J40: =IFERROR(IF($A40>=VLOOKUP($B40,Ref_Acuerdos!$A:$E,3,FALSE()),VLOOKUP($B40,Ref_Acuerdos!$A:$E,4,FALSE()),""),"") | K40: =IFERROR(IF($A40>=VLOOKUP($B40,Ref_Acuerdos!$A:$E,3,FALSE()),VLOOKUP($B40,Ref_Acuerdos!$A:$E,5,FALSE()),"Sin FTA/PTA vigente ese año - arancel NMF"),"Sin FTA/PTA identificado - arancel NMF") -> Sin FTA/PTA vigente ese año - arancel NMF
A41: 2009 | B41: Sweden | C41: =IFERROR(VLOOKUP($B41,Ref_Continente!$A:$B,2,FALSE()),"Sin clasificar") -> Europe | D41: 16290 | E41: 4099 | F41: 10000 | G41: 4.3431171e+11 | H41: =IFERROR(IF(AND(VLOOKUP($B41,Ref_Acuerdos!$A:$E,2,FALSE())="FTA",$A41>=VLOOKUP($B41,Ref_Acuerdos!$A:$E,3,FALSE())),1,0),0) -> 0 | I41: =IFERROR(IF(AND(VLOOKUP($B41,Ref_Acuerdos!$A:$E,2,FALSE())="PTA",$A41>=VLOOKUP($B41,Ref_Acuerdos!$A:$E,3,FALSE())),1,0),0) -> 0 | J41: =IFERROR(IF($A41>=VLOOKUP($B41,Ref_Acuerdos!$A:$E,3,FALSE()),VLOOKUP($B41,Ref_Acuerdos!$A:$E,4,FALSE()),""),"") | K41: =IFERROR(IF($A41>=VLOOKUP($B41,Ref_Acuerdos!$A:$E,3,FALSE()),VLOOKUP($B41,Ref_Acuerdos!$A:$E,5,FALSE()),"Sin FTA/PTA vigente ese año - arancel NMF"),"Sin FTA/PTA identificado - arancel NMF") -> Sin FTA/PTA vigente ese año - arancel NMF
A42: 2009 | B42: Uruguay | C42: =IFERROR(VLOOKUP($B42,Ref_Continente!$A:$B,2,FALSE()),"Sin clasificar") -> South America | D42: 11311 | E42: 2701 | F42: 4650 | G42: 3.2708319e+10 | H42: =IFERROR(IF(AND(VLOOKUP($B42,Ref_Acuerdos!$A:$E,2,FALSE())="FTA",$A42>=VLOOKUP($B42,Ref_Acuerdos!$A:$E,3,FALSE())),1,0),0) -> 0 | I42: =IFERROR(IF(AND(VLOOKUP($B42,Ref_Acuerdos!$A:$E,2,FALSE())="PTA",$A42>=VLOOKUP($B42,Ref_Acuerdos!$A:$E,3,FALSE())),1,0),0) -> 1 | J42: =IFERROR(IF($A42>=VLOOKUP($B42,Ref_Acuerdos!$A:$E,3,FALSE()),VLOOKUP($B42,Ref_Acuerdos!$A:$E,4,FALSE()),""),"") -> 5 | K42: =IFERROR(IF($A42>=VLOOKUP($B42,Ref_Acuerdos!$A:$E,3,FALSE()),VLOOKUP($B42,Ref_Acuerdos!$A:$E,5,FALSE()),"Sin FTA/PTA vigente ese año - arancel NMF"),"Sin FTA/PTA identificado - arancel NMF") -> Ecuador-Mercosur ACE 59 - preferencias parciales (tarifa referencial)
A43: 2009 | B43: United Arab Emirates | C43: =IFERROR(VLOOKUP($B43,Ref_Continente!$A:$B,2,FALSE()),"Sin clasificar") -> Asia | D43: 9377 | E43: 1668 | F43: 14200 | G43: 2.5354736e+11 | H43: =IFERROR(IF(AND(VLOOKUP($B43,Ref_Acuerdos!$A:$E,2,FALSE())="FTA",$A43>=VLOOKUP($B43,Ref_Acuerdos!$A:$E,3,FALSE())),1,0),0) -> 0 | I43: =IFERROR(IF(AND(VLOOKUP($B43,Ref_Acuerdos!$A:$E,2,FALSE())="PTA",$A43>=VLOOKUP($B43,Ref_Acuerdos!$A:$E,3,FALSE())),1,0),0) -> 0 | J43: =IFERROR(IF($A43>=VLOOKUP($B43,Ref_Acuerdos!$A:$E,3,FALSE()),VLOOKUP($B43,Ref_Acuerdos!$A:$E,4,FALSE()),""),"") | K43: =IFERROR(IF($A43>=VLOOKUP($B43,Ref_Acuerdos!$A:$E,3,FALSE()),VLOOKUP($B43,Ref_Acuerdos!$A:$E,5,FALSE()),"Sin FTA/PTA vigente ese año - arancel NMF"),"Sin FTA/PTA identificado - arancel NMF") -> Sin FTA/PTA identificado - arancel NMF
A44: 2009 | B44: Nicaragua | C44: =IFERROR(VLOOKUP($B44,Ref_Continente!$A:$B,2,FALSE()),"Sin clasificar") -> North America | D44: 8653 | E44: 1632 | F44: 1730 | G44: 8.2987025e+09 | H44: =IFERROR(IF(AND(VLOOKUP($B44,Ref_Acuerdos!$A:$E,2,FALSE())="FTA",$A44>=VLOOKUP($B44,Ref_Acuerdos!$A:$E,3,FALSE())),1,0),0) -> 0 | I44: =IFERROR(IF(AND(VLOOKUP($B44,Ref_Acuerdos!$A:$E,2,FALSE())="PTA",$A44>=VLOOKUP($B44,Ref_Acuerdos!$A:$E,3,FALSE())),1,0),0) -> 1 | J44: =IFERROR(IF($A44>=VLOOKUP($B44,Ref_Acuerdos!$A:$E,3,FALSE()),VLOOKUP($B44,Ref_Acuerdos!$A:$E,4,FALSE()),""),"") -> 10 | K44: =IFERROR(IF($A44>=VLOOKUP($B44,Ref_Acuerdos!$A:$E,3,FALSE()),VLOOKUP($B44,Ref_Acuerdos!$A:$E,5,FALSE()),"Sin FTA/PTA vigente ese año - arancel NMF"),"Sin FTA/PTA identificado - arancel NMF") -> ALADI - Acuerdo de Alcance Parcial (preferencia limitada, tarifa referencial)
A45: 2009 | B45: Saudi Arabia | C45: =IFERROR(VLOOKUP($B45,Ref_Continente!$A:$B,2,FALSE()),"Sin clasificar") -> Asia | D45: 7644 | E45: 2128 | F45: 13800 | G45: 4.2909787e+11 | H45: =IFERROR(IF(AND(VLOOKUP($B45,Ref_Acuerdos!$A:$E,2,FALSE())="FTA",$A45>=VLOOKUP($B45,Ref_Acuerdos!$A:$E,3,FALSE())),1,0),0) -> 0 | I45: =IFERROR(IF(AND(VLOOKUP($B45,Ref_Acuerdos!$A:$E,2,FALSE())="PTA",$A45>=VLOOKUP($B45,Ref_Acuerdos!$A:$E,3,FALSE())),1,0),0) -> 0 | J45: =IFERROR(IF($A45>=VLOOKUP($B45,Ref_Acuerdos!$A:$E,3,FALSE()),VLOOKUP($B45,Ref_Acuerdos!$A:$E,4,FALSE()),""),"") | K45: =IFERROR(IF($A45>=VLOOKUP($B45,Ref_Acuerdos!$A:$E,3,FALSE()),VLOOKUP($B45,Ref_Acuerdos!$A:$E,5,FALSE()),"Sin FTA/PTA vigente ese año - arancel NMF"),"Sin FTA/PTA identificado - arancel NMF") -> Sin FTA/PTA identificado - arancel NMF
...

Sheet Continente_x_Anio
A1: Año | B1: North America | C1: South America | D1: Europe | E1: Asia | F1: Africa | G1: Oceania | H1: Sin clasificar
A2: 2008 | B2: =SUMIFS(Datos!$D:$D,Datos!$A:$A,$A2,Datos!$C:$C,B$1) -> 250714 | C2: =SUMIFS(Datos!$D:$D,Datos!$A:$A,$A2,Datos!$C:$C,C$1) -> 14458 | D2: =SUMIFS(Datos!$D:$D,Datos!$A:$A,$A2,Datos!$C:$C,D$1) -> 286833 | E2: =SUMIFS(Datos!$D:$D,Datos!$A:$A,$A2,Datos!$C:$C,E$1) -> 1532 | F2: =SUMIFS(Datos!$D:$D,Datos!$A:$A,$A2,Datos!$C:$C,F$1) -> 0 | G2: =SUMIFS(Datos!$D:$D,Datos!$A:$A,$A2,Datos!$C:$C,G$1) -> 156 | H2: =SUMIFS(Datos!$D:$D,Datos!$A:$A,$A2,Datos!$C:$C,H$1) -> 2029
A3: 2009 | B3: =SUMIFS(Datos!$D:$D,Datos!$A:$A,$A3,Datos!$C:$C,B$1) -> 2231751 | C3: =SUMIFS(Datos!$D:$D,Datos!$A:$A,$A3,Datos!$C:$C,C$1) -> 225157 | D3: =SUMIFS(Datos!$D:$D,Datos!$A:$A,$A3,Datos!$C:$C,D$1) -> 5323041 | E3: =SUMIFS(Datos!$D:$D,Datos!$A:$A,$A3,Datos!$C:$C,E$1) -> 298973 | F3: =SUMIFS(Datos!$D:$D,Datos!$A:$A,$A3,Datos!$C:$C,F$1) -> 0 | G3: =SUMIFS(Datos!$D:$D,Datos!$A:$A,$A3,Datos!$C:$C,G$1) -> 71046 | H3: =SUMIFS(Datos!$D:$D,Datos!$A:$A,$A3,Datos!$C:$C,H$1) -> 0
A4: 2010 | B4: =SUMIFS(Datos!$D:$D,Datos!$A:$A,$A4,Datos!$C:$C,B$1) -> 4913774 | C4: =SUMIFS(Datos!$D:$D,Datos!$A:$A,$A4,Datos!$C:$C,C$1) -> 354666 | D4: =SUMIFS(Datos!$D:$D,Datos!$A:$A,$A4,Datos!$C:$C,D$1) -> 10865744 | E4: =SUMIFS(Datos!$D:$D,Datos!$A:$A,$A4,Datos!$C:$C,E$1) -> 904487 | F4: =SUMIFS(Datos!$D:$D,Datos!$A:$A,$A4,Datos!$C:$C,F$1) -> 0 | G4: =SUMIFS(Datos!$D:$D,Datos!$A:$A,$A4,Datos!$C:$C,G$1) -> 25781 | H4: =SUMIFS(Datos!$D:$D,Datos!$A:$A,$A4,Datos!$C:$C,H$1) -> 113917
A5: 2011 | B5: =SUMIFS(Datos!$D:$D,Datos!$A:$A,$A5,Datos!$C:$C,B$1) -> 3343338 | C5: =SUMIFS(Datos!$D:$D,Datos!$A:$A,$A5,Datos!$C:$C,C$1) -> 735739 | D5: =SUMIFS(Datos!$D:$D,Datos!$A:$A,$A5,Datos!$C:$C,D$1) -> 8726795 | E5: =SUMIFS(Datos!$D:$D,Datos!$A:$A,$A5,Datos!$C:$C,E$1) -> 1351265 | F5: =SUMIFS(Datos!$D:$D,Datos!$A:$A,$A5,Datos!$C:$C,F$1) -> 0 | G5: =SUMIFS(Datos!$D:$D,Datos!$A:$A,$A5,Datos!$C:$C,G$1) -> 6518 | H5: =SUMIFS(Datos!$D:$D,Datos!$A:$A,$A5,Datos!$C:$C,H$1) -> 473926
A6: 2012 | B6: =SUMIFS(Datos!$D:$D,Datos!$A:$A,$A6,Datos!$C:$C,B$1) -> 4293464 | C6: =SUMIFS(Datos!$D:$D,Datos!$A:$A,$A6,Datos!$C:$C,C$1) -> 865366 | D6: =SUMIFS(Datos!$D:$D,Datos!$A:$A,$A6,Datos!$C:$C,D$1) -> 9254745 | E6: =SUMIFS(Datos!$D:$D,Datos!$A:$A,$A6,Datos!$C:$C,E$1) -> 2271926 | F6: =SUMIFS(Datos!$D:$D,Datos!$A:$A,$A6,Datos!$C:$C,F$1) -> 0 | G6: =SUMIFS(Datos!$D:$D,Datos!$A:$A,$A6,Datos!$C:$C,G$1) -> 22033 | H6: =SUMIFS(Datos!$D:$D,Datos!$A:$A,$A6,Datos!$C:$C,H$1) -> 435071
A7: 2013 | B7: =SUMIFS(Datos!$D:$D,Datos!$A:$A,$A7,Datos!$C:$C,B$1) -> 8351974 | C7: =SUMIFS(Datos!$D:$D,Datos!$A:$A,$A7,Datos!$C:$C,C$1) -> 742768 | D7: =SUMIFS(Datos!$D:$D,Datos!$A:$A,$A7,Datos!$C:$C,D$1) -> 8282815 | E7: =SUMIFS(Datos!$D:$D,Datos!$A:$A,$A7,Datos!$C:$C,E$1) -> 1223648 | F7: =SUMIFS(Datos!$D:$D,Datos!$A:$A,$A7,Datos!$C:$C,F$1) -> 0 | G7: =SUMIFS(Datos!$D:$D,Datos!$A:$A,$A7,Datos!$C:$C,G$1) -> 10838 | H7: =SUMIFS(Datos!$D:$D,Datos!$A:$A,$A7,Datos!$C:$C,H$1) -> 180
A8: 2014 | B8: =SUMIFS(Datos!$D:$D,Datos!$A:$A,$A8,Datos!$C:$C,B$1) -> 3597184 | C8: =SUMIFS(Datos!$D:$D,Datos!$A:$A,$A8,Datos!$C:$C,C$1) -> 374500 | D8: =SUMIFS(Datos!$D:$D,Datos!$A:$A,$A8,Datos!$C:$C,D$1) -> 9625831 | E8: =SUMIFS(Datos!$D:$D,Datos!$A:$A,$A8,Datos!$C:$C,E$1) -> 3560466 | F8: =SUMIFS(Datos!$D:$D,Datos!$A:$A,$A8,Datos!$C:$C,F$1) -> 0 | G8: =SUMIFS(Datos!$D:$D,Datos!$A:$A,$A8,Datos!$C:$C,G$1) -> 14122 | H8: =SUMIFS(Datos!$D:$D,Datos!$A:$A,$A8,Datos!$C:$C,H$1) -> 0
A9: 2015 | B9: =SUMIFS(Datos!$D:$D,Datos!$A:$A,$A9,Datos!$C:$C,B$1) -> 2735463 | C9: =SUMIFS(Datos!$D:$D,Datos!$A:$A,$A9,Datos!$C:$C,C$1) -> 410587 | D9: =SUMIFS(Datos!$D:$D,Datos!$A:$A,$A9,Datos!$C:$C,D$1) -> 8412542 | E9: =SUMIFS(Datos!$D:$D,Datos!$A:$A,$A9,Datos!$C:$C,E$1) -> 5394035 | F9: =SUMIFS(Datos!$D:$D,Datos!$A:$A,$A9,Datos!$C:$C,F$1) -> 84 | G9: =SUMIFS(Datos!$D:$D,Datos!$A:$A,$A9,Datos!$C:$C,G$1) -> 235577 | H9: =SUMIFS(Datos!$D:$D,Datos!$A:$A,$A9,Datos!$C:$C,H$1) -> 0
A10: 2016 | B10: =SUMIFS(Datos!$D:$D,Datos!$A:$A,$A10,Datos!$C:$C,B$1) -> 2571728 | C10: =SUMIFS(Datos!$D:$D,Datos!$A:$A,$A10,Datos!$C:$C,C$1) -> 435015 | D10: =SUMIFS(Datos!$D:$D,Datos!$A:$A,$A10,Datos!$C:$C,D$1) -> 6825699 | E10: =SUMIFS(Datos!$D:$D,Datos!$A:$A,$A10,Datos!$C:$C,E$1) -> 4805325 | F10: =SUMIFS(Datos!$D:$D,Datos!$A:$A,$A10,Datos!$C:$C,F$1) -> 0 | G10: =SUMIFS(Datos!$D:$D,Datos!$A:$A,$A10,Datos!$C:$C,G$1) -> 304513 | H10: =SUMIFS(Datos!$D:$D,Datos!$A:$A,$A10,Datos!$C:$C,H$1) -> 0
A11: 2017 | B11: =SUMIFS(Datos!$D:$D,Datos!$A:$A,$A11,Datos!$C:$C,B$1) -> 2245593 | C11: =SUMIFS(Datos!$D:$D,Datos!$A:$A,$A11,Datos!$C:$C,C$1) -> 506368 | D11: =SUMIFS(Datos!$D:$D,Datos!$A:$A,$A11,Datos!$C:$C,D$1) -> 8937578 | E11: =SUMIFS(Datos!$D:$D,Datos!$A:$A,$A11,Datos!$C:$C,E$1) -> 5459552 | F11: =SUMIFS(Datos!$D:$D,Datos!$A:$A,$A11,Datos!$C:$C,F$1) -> 200 | G11: =SUMIFS(Datos!$D:$D,Datos!$A:$A,$A11,Datos!$C:$C,G$1) -> 423529 | H11: =SUMIFS(Datos!$D:$D,Datos!$A:$A,$A11,Datos!$C:$C,H$1) -> 0
A12: 2018 | B12: =SUMIFS(Datos!$D:$D,Datos!$A:$A,$A12,Datos!$C:$C,B$1) -> 2118425 | C12: =SUMIFS(Datos!$D:$D,Datos!$A:$A,$A12,Datos!$C:$C,C$1) -> 597183 | D12: =SUMIFS(Datos!$D:$D,Datos!$A:$A,$A12,Datos!$C:$C,D$1) -> 10294662 | E12: =SUMIFS(Datos!$D:$D,Datos!$A:$A,$A12,Datos!$C:$C,E$1) -> 5679385 | F12: =SUMIFS(Datos!$D:$D,Datos!$A:$A,$A12,Datos!$C:$C,F$1) -> 0 | G12: =SUMIFS(Datos!$D:$D,Datos!$A:$A,$A12,Datos!$C:$C,G$1) -> 266428 | H12: =SUMIFS(Datos!$D:$D,Datos!$A:$A,$A12,Datos!$C:$C,H$1) -> 0
A13: 2019 | B13: =SUMIFS(Datos!$D:$D,Datos!$A:$A,$A13,Datos!$C:$C,B$1) -> 2320693 | C13: =SUMIFS(Datos!$D:$D,Datos!$A:$A,$A13,Datos!$C:$C,C$1) -> 530078 | D13: =SUMIFS(Datos!$D:$D,Datos!$A:$A,$A13,Datos!$C:$C,D$1) -> 8757063 | E13: =SUMIFS(Datos!$D:$D,Datos!$A:$A,$A13,Datos!$C:$C,E$1) -> 5860639 | F13: =SUMIFS(Datos!$D:$D,Datos!$A:$A,$A13,Datos!$C:$C,F$1) -> 0 | G13: =SUMIFS(Datos!$D:$D,Datos!$A:$A,$A13,Datos!$C:$C,G$1) -> 242487 | H13: =SUMIFS(Datos!$D:$D,Datos!$A:$A,$A13,Datos!$C:$C,H$1) -> 0
... A18: 2024 | B18: =SUMIFS(Datos!$D:$D,Datos!$A:$A,$A18,Datos!$C:$C,B$1) -> 3825835 | C18: =SUMIFS(Datos!$D:$D,Datos!$A:$A,$A18,Datos!$C:$C,C$1) -> 979807 | D18: =SUMIFS(Datos!$D:$D,Datos!$A:$A,$A18,Datos!$C:$C,D$1) -> 3424082 | E18: =SUMIFS(Datos!$D:$D,Datos!$A:$A,$A18,Datos!$C:$C,E$1) -> 9042703 | F18: =SUMIFS(Datos!$D:$D,Datos!$A:$A,$A18,Datos!$C:$C,F$1) -> 755 | G18: =SUMIFS(Datos!$D:$D,Datos!$A:$A,$A18,Datos!$C:$C,G$1) -> 511737 | H18: =SUMIFS(Datos!$D:$D,Datos!$A:$A,$A18,Datos!$C:$C,H$1) -> 0

Sheet Resumen_Pais
A1: Pais (Partner) | B1: Continente | C1: Valor Exportado Total (US$) | D1: Distancia Ecuador (km) | E1: PIB pais importador 2024 (US$)
A2: Russian Federation | B2: =IFERROR(VLOOKUP($A2,Datos!$B:$C,2,FALSE()),"Sin clasificar") -> Europe | C2: =SUMIF(Datos!$B:$B,$A2,Datos!$D:$D) -> 75350094 | D2: =IFERROR(AVERAGEIF(Datos!$B:$B,$A2,Datos!$F:$F),"") -> 12000 | E2: =IFERROR(SUMIFS(Datos!$G:$G,Datos!$B:$B,$A2,Datos!$A:$A,2024),"") -> 2.1738358e+12
A3: Japan | B3: =IFERROR(VLOOKUP($A3,Datos!$B:$C,2,FALSE()),"Sin clasificar") -> Asia | C3: =SUMIF(Datos!$B:$B,$A3,Datos!$D:$D) -> 64147663 | D3: =IFERROR(AVERAGEIF(Datos!$B:$B,$A3,Datos!$F:$F),"") -> 14500 | E3: =IFERROR(SUMIFS(Datos!$G:$G,Datos!$B:$B,$A3,Datos!$A:$A,2024),"") -> 4.0275975e+12
A4: USA | B4: =IFERROR(VLOOKUP($A4,Datos!$B:$C,2,FALSE()),"Sin clasificar") -> North America | C4: =SUMIF(Datos!$B:$B,$A4,Datos!$D:$D) -> 53108153 | D4: =IFERROR(AVERAGEIF(Datos!$B:$B,$A4,Datos!$F:$F),"") -> 4550 | E4: =IFERROR(SUMIFS(Datos!$G:$G,Datos!$B:$B,$A4,Datos!$A:$A,2024),"") -> 2.8750956e+13
A5: Netherlands | B5: =IFERROR(VLOOKUP($A5,Datos!$B:$C,2,FALSE()),"Sin clasificar") -> Europe | C5: =SUMIF(Datos!$B:$B,$A5,Datos!$D:$D) -> 22010517 | D5: =IFERROR(AVERAGEIF(Datos!$B:$B,$A5,Datos!$F:$F),"") -> 9300 | E5: =IFERROR(SUMIFS(Datos!$G:$G,Datos!$B:$B,$A5,Datos!$A:$A,2024),"") -> 1.2149277e+12
A6: Kazakhstan | B6: =IFERROR(VLOOKUP($A6,Datos!$B:$C,2,FALSE()),"Sin clasificar") -> Asia | C6: =SUMIF(Datos!$B:$B,$A6,Datos!$D:$D) -> 15232905 | D6: =IFERROR(AVERAGEIF(Datos!$B:$B,$A6,Datos!$F:$F),"") -> 13600 | E6: =IFERROR(SUMIFS(Datos!$G:$G,Datos!$B:$B,$A6,Datos!$A:$A,2024),"") -> 2.9148027e+11
A7: Ukraine | B7: =IFERROR(VLOOKUP($A7,Datos!$B:$C,2,FALSE()),"Sin clasificar") -> Europe | C7: =SUMIF(Datos!$B:$B,$A7,Datos!$D:$D) -> 7547669 | D7: =IFERROR(AVERAGEIF(Datos!$B:$B,$A7,Datos!$F:$F),"") -> 11 | E7: =IFERROR(SUMIFS(Datos!$G:$G,Datos!$B:$B,$A7,Datos!$A:$A,2024),"") -> 1.9074126e+11
A8: Spain | B8: =IFERROR(VLOOKUP($A8,Datos!$B:$C,2,FALSE()),"Sin clasificar") -> Europe | C8: =SUMIF(Datos!$B:$B,$A8,Datos!$D:$D) -> 7505896 | D8: =IFERROR(AVERAGEIF(Datos!$B:$B,$A8,Datos!$F:$F),"") -> 8700 | E8: =IFERROR(SUMIFS(Datos!$G:$G,Datos!$B:$B,$A8,Datos!$A:$A,2024),"") -> 1.7256717e+12
A9: Chile | B9: =IFERROR(VLOOKUP($A9,Datos!$B:$C,2,FALSE()),"Sin clasificar") -> South America | C9: =SUMIF(Datos!$B:$B,$A9,Datos!$D:$D) -> 4156202 | D9: =IFERROR(AVERAGEIF(Datos!$B:$B,$A9,Datos!$F:$F),"") -> 2600 | E9: =IFERROR(SUMIFS(Datos!$G:$G,Datos!$B:$B,$A9,Datos!$A:$A,2024),"") -> 3.3026714e+11
A10: Belarus | B10: =IFERROR(VLOOKUP($A10,Datos!$B:$C,2,FALSE()),"Sin clasificar") -> Europe | C10: =SUMIF(Datos!$B:$B,$A10,Datos!$D:$D) -> 3741061 | D10: =IFERROR(AVERAGEIF(Datos!$B:$B,$A10,Datos!$F:$F),"") -> 10600 | E10: =IFERROR(SUMIFS(Datos!$G:$G,Datos!$B:$B,$A10,Datos!$A:$A,2024),"") -> 7.5961865e+10
A11: Australia | B11: =IFERROR(VLOOKUP($A11,Datos!$B:$C,2,FALSE()),"Sin clasificar") -> Oceania | C11: =SUMIF(Datos!$B:$B,$A11,Datos!$D:$D) -> 3374803 | D11: =IFERROR(AVERAGEIF(Datos!$B:$B,$A11,Datos!$F:$F),"") -> 14000 | E11: =IFERROR(SUMIFS(Datos!$G:$G,Datos!$B:$B,$A11,Datos!$A:$A,2024),"") -> 1.7570225e+12
A12: Italy | B12: =IFERROR(VLOOKUP($A12,Datos!$B:$C,2,FALSE()),"Sin clasificar") -> Europe | C12: =SUMIF(Datos!$B:$B,$A12,Datos!$D:$D) -> 2434084 | D12: =IFERROR(AVERAGEIF(Datos!$B:$B,$A12,Datos!$F:$F),"") -> 10100 | E12: =IFERROR(SUMIFS(Datos!$G:$G,Datos!$B:$B,$A12,Datos!$A:$A,2024),"") -> 2.3808251e+12
A13: Dominican Rep. | B13: =IFERROR(VLOOKUP($A13,Datos!$B:$C,2,FALSE()),"Sin clasificar") -> North America | C13: =SUMIF(Datos!$B:$B,$A13,Datos!$D:$D) -> 1769895 | D13: =IFERROR(AVERAGEIF(Datos!$B:$B,$A13,Datos!$F:$F),"") -> 2200 | E13: =IFERROR(SUMIFS(Datos!$G:$G,Datos!$B:$B,$A13,Datos!$A:$A,2024),"") -> 1.2428225e+11
... A113: Saint Vincent and the Grenadines | B113: =IFERROR(VLOOKUP($A113,Datos!$B:$C,2,FALSE()),"Sin clasificar") -> North America | C113: =SUMIF(Datos!$B:$B,$A113,Datos!$D:$D) -> 40 | D113: =IFERROR(AVERAGEIF(Datos!$B:$B,$A113,Datos!$F:$F),"") -> 2650 | E113: =IFERROR(SUMIFS(Datos!$G:$G,Datos!$B:$B,$A113,Datos!$A:$A,2024),"") -> 0

Sheet Analisis
A1: Analisis: Claveles (HS 060312) - continente / distancia / PIB, 2008-2024
A3: 1) Por continente (valor exportado total, US$)
A5: Continente | B5: Valor exportado (US$)
A6: North America | B6: =SUMIF(Datos!$C:$C,$A6,Datos!$D:$D) -> 58775212
A7: South America | B7: =SUMIF(Datos!$C:$C,$A7,Datos!$D:$D) -> 9313586
A8: Europe | B8: =SUMIF(Datos!$C:$C,$A8,Datos!$D:$D) -> 125593959
A9: Asia | B9: =SUMIF(Datos!$C:$C,$A9,Datos!$D:$D) -> 83532577
A10: Africa | B10: =SUMIF(Datos!$C:$C,$A10,Datos!$D:$D) -> 2107
A11: Oceania | B11: =SUMIF(Datos!$C:$C,$A11,Datos!$D:$D) -> 3408833
A12: Sin clasificar | B12: =SUMIF(Datos!$C:$C,$A12,Datos!$D:$D) -> 1025123
A14: 2) Correlacion valor exportado vs distancia a Ecuador (Pearson, -1 a 1): | D14: =CORREL(Resumen_Pais!$C$2:$C$113,Resumen_Pais!$D$2:$D$113) -> 0.036881598
A15: Interpretacion: valor cercano a 0 => la distancia NO explica el volumen exportado.
A17: 3) Correlacion valor exportado vs PIB del pais importador (Pearson, -1 a 1): | D17: =CORREL(Resumen_Pais!$C$2:$C$113,Resumen_Pais!$E$2:$E$113) -> 0.54885813
A18: Interpretacion: valor cercano a 1 => a mayor PIB del pais importador, mayor valor exportado por Ecuador.

Sheet Graficos
